Workbook

Sheet EFM
M1: Ra | N1: Rp | O1: vRp | P1: Rfe | Q1: NfE | R1: Rfa | S1: Ca | T1: P | V1: Mg | W1: K | X1: Na | Y1: Cl | Z1: Fe | AA1: Cu | AB1: Zn | AC1: Mn | AD1: Jod | AE1: Selen | AG1: Vit. A | AI1: b-Carotinoide | AL1: Vit. D3 | AN1: Vit. E | AO1: Vit. B1 | AP1: Vit. B2 | AQ1: Vit. B6 | AR1: Vit. B12 | AS1: Biotin | AT1: Niacin | AU1: Pantothensäure | AV1: Folsäure | AW1: Vit C | AX1: Vit K | AY1: Cholin
D2: 1 | E2: 2 | F2: 3 | G2: 4 | H2: 5 | I2: 6 | J2: 7 | K2: 8 | L2: 9 | M2: 14 | N2: 15 | O2: 16 | P2: 17 | Q2: 18 | R2: 19 | S2: 64 | T2: 65 | V2: 66 | W2: 67 | X2: 68 | Y2: 69 | Z2: 70 | AA2: 71 | AB2: 72 | AC2: 73 | AD2: 74 | AE2: 75 | AF2: 76 | AG2: 77 | AH2: 78 | AI2: 79 | AJ2: 80 | AK2: 81 | AL2: 82 | AM2: 83 | AN2: 84 | AO2: 85 | AP2: 86 | AQ2: 87 | AR2: 88 | AS2: 89 | AT2: 90 | AU2: 91 | AV2: 92 | AW2: 93 | AX2: 94 | AY2: 95 | BA2: 96 | BC2: 97 | BD2: 98 | BE2: 99 | BF2: 100 | BG2: 101 | BH2: 102 | BI2: 103 | BJ2: 104 | BK2: 105 | BL2: 106
D3: Identifier | E3: Typ | F3: Spezies | G3: Kategorie | H3: Nummer fortlaufend in Kategorie | I3: Nummer fortlaufend | J3: Kategorie-Nummer | K3: Anfangsbuchstabe | L3: Futtermittel | M3: Ra [g]/[100g] | N3: Rp [g]/[100g] | O3: Rp [g]/[100g] | P3: Rfe [g]/[100g] | Q3: NfE [g]/[100g] | R3: Rfa [g]/[100g] | S3: Ca [mg]/[100g] | T3: P [mg]/[100g] | U3: Ca/P-Verhältnis | V3: Mg [mg]/[100g] | W3: K [mg]/[100g] | X3: Na [mg]/[100g] | Y3: Cl [mg]/[100g] | Z3: Fe [mg]/[100g] | AA3: Cu [mg]/[100g] | AB3: Zn [mg]/[100g] | AC3: Mn [mg]/[100g] | AD3: Jod [µg]/[100g] | AE3: Selen [µg]/[100g] | AF3: Vit. A [µg]/[100g] | AG3: Vit. A [IE]/[100g] | AH3: Retinoläquivalent [µg]/[100g] | AI3: b-Carotinoide [µg]/[100g] | AJ3: alle Carotinoide [µg]/[100g] | AK3: Vit. D3 [IE]/[100g] | AL3: Vit. D3 [µg]/[100g] | AM3: Vit E activity [mg]/[100g] | AN3: Vit. E (a-Tocopherol) [mg]/[100g] | AO3: Vit. B1 [mg]/[100g] | AP3: Vit. B2 [mg]/[100g] | AQ3: Vit. B6 [mg]/[100g] | AR3: Vit. B12 [µg]/[100g] | AS3: Biotin [µg]/[100g] | AT3: Niacin [mg]/[100g] | AU3: Pantothensäure [mg]/[100g] | AV3: Folsäure [µg]/[100g] | AW3: Vit C [mg]/[100g] | AX3: Vit K [mg]/[100g] | AY3: Cholin [mg]/[100g] | AZ3: Taurin [mg]/[100g] | BA3: Preis (€) pro kg | BB3: Empfolene Dosierung (g pro Tag) | BC3: Name komplett | BD3: Marke | BE3: Produkt (bei Fertigfutter) | BF3: Ra [%TS] | BG3: Rp [%TS] | BI3: Rfe [%TS] | BJ3: NfE [%TS] | BK3: Rfa [%TS] | BL3: bei Fertigfutter: Zusammensetzung | BM3: Links
D4: =E4&""&F4&""&G4&""&H4 -> ErgänzungsfuttermittelKatzeVitamin-Spurenelement-Präparat | E4: Ergänzungsfuttermittel | F4: Katze | G4: Vitamin-Spurenelement-Präparat | L4: Revital Plus | M4: =BF4 -> 5.7 | N4: =BG4 -> 10.3 | P4: =BI4 -> 5.8 | R4: =BK4 -> 1.4 | S4: 1300 | T4: 1000 | U4: =IF(S4="","",S4/T4) -> 1.3 | V4: 1000 | W4: 1300 | X4: 100 | Z4: 210 | AC4: 10 | AF4: =AG4*$BO$13 -> 4500 | AG4: 15000 | AK4: 1500 | AL4: =AK4*$BO$14 -> 37.5 | AN4: 300 | AO4: 3 | AP4: 75 | AQ4: 3 | AR4: 150 | AT4: 50 | AU4: 30 | AV4: 600 | AW4: 300 | AY4: 1000 | AZ4: 160 | BA4: 96.96 | BC4: Revital Plus | BD4: Vet-Concept | BE4: Ergänzungsfuttermittel | BF4: 5.7 | BG4: 10.3 | BI4: 5.8 | BK4: 1.4 | BL4: Maltodextrin, hydrolysiertes Volleipulver, Molkepulver, Leinsamen (gemahlen), Seealgenmehl, Leinöl, Grünlippmuschel* (Perna canaliculus) (1 %), Ginseng (1 %), * getrocknet | BM4: https://www.vet-concept.at/p/fuer-den-hund-revital-plus-150g-500g?prod_number=7708&gad_source=1&gclid=CjwKCAjw5v2wBhBrEiwAXDDoJZr_GZsVM5G3yLJnLQN7A1Se8Asq66qXCdNAnqcZ2sCvQPCUq3KvFRoCs30QAvD_BwE
D5: =E5&""&F5&""&G5&""&H5 -> ErgänzungsfuttermittelKatzeVitamin-Spurenelement-Präparat | E5: Ergänzungsfuttermittel | F5: Katze | G5: Vitamin-Spurenelement-Präparat | L5: Catfortan | M5: =BF5 -> 19.5 | N5: =BG5 -> 34.4 | P5: =BI5 -> 4.5 | R5: =BK5 -> 1.7 | S5: 4490 | T5: 2200 | U5: =IF(S5="","",S5/T5) -> 2.0409091 | V5: 250 | W5: 2000 | Z5: 370 | AA5: 7.5 | AB5: 30 | AC5: 25 | AD5: 1200 | AE5: 50 | AF5: =AG5*$BO$13 -> 6000 | AG5: 20000 | AK5: 1000 | AL5: =AK5*$BO$14 -> 25 | AN5: 150 | AO5: 40 | AP5: 26 | AQ5: 16 | AR5: 100 | AS5: 600 | AT5: 190 | AU5: 50 | AV5: 4000 | AY5: 300 | AZ5: 1000 | BA5: 49.5 | BB5: 1 | BC5: Catfortan | BD5: Fortan | BE5: Ergänzungsfuttermittel | BF5: 19.5 | BG5: 34.4 | BI5: 4.5 | BK5: 1.7 | BL5: Hefen, Mineralstoffe, Milch/Molkereierzeugnisse,pflanzliche Nebenerzeugnisse (als Trockenkräuter), Kollagenhydrolysat, Algen, Hämoglobin, Saaten | BM5: https://fortan.de/CATFORTAN-Tabletten-fuer-Katzen/550
D6: =E6&""&F6&""&G6&""&H6 -> ErgänzungsfuttermittelKatzeVitamin-Spurenelement-Präparat | E6: Ergänzungsfuttermittel | F6: Katze | G6: Vitamin-Spurenelement-Präparat | L6: Biotin-plus MSM Tabs | M6: =BF6 -> 7.5 | N6: =BG6 -> 15.3 | P6: =BI6 -> 2.4 | R6: =BK6 -> 1.6 | U6: =IF(S6="","",S6/T6) | AB6: 300 | AF6: =AG6*$BO$13 -> 0 | AL6: =AK6*$BO$14 -> 0 | AN6: 250 | AO6: 120 | AP6: 80 | AQ6: 100 | AR6: 600 | AS6: 110000 | AU6: 150 | BA6: 78.5 | BB6: 0.8 | BC6: Biotin-plus MSM Tabs | BD6: Fortan | BE6: Ergänzungsfuttermittel | BF6: 7.5 | BG6: 15.3 | BI6: 2.4 | BK6: 1.6 | BL6: Hefen, MSM (Methyl Sulfonyl Methan) 7 %, Magnesiumstearat, Saaten | BM6: https://fortan.de/Biotin-plus-MSM-Tabs/582b
D7: =E7&""&F7&""&G7&""&H7 -> ErgänzungsfuttermittelKatzeVitamin-Spurenelement-Präparat | E7: Ergänzungsfuttermittel | F7: Katze | G7: Vitamin-Spurenelement-Präparat | L7: Carni-Fortan | M7: =BF7 -> 18.5 | N7: =BG7 -> 32.9 | P7: =BI7 -> 4.3 | R7: =BK7 -> 3.7 | U7: =IF(S7="","",S7/T7) | Z7: 300 | AF7: =AG7*$BO$13 -> 0 | AL7: =AK7*$BO$14 -> 0 | AN7: 1000 | AO7: 16 | AQ7: 50 | AR7: 240 | AS7: 2000 | AT7: 100 | AW7: 500 | AZ7: 2500 | BA7: 74 | BB7: 4.5 | BC7: Carni-Fortan | BD7: Fortan | BE7: Ergänzungsfuttermittel | BF7: 18.5 | BG7: 32.9 | BI7: 4.3 | BK7: 3.7 | BL7: Hefen, pflanzliche Nebenerzeugnisse, Kollagenhydrolysat, Mineralstoffe, Glucose | BM7: https://fortan.de/Carni-Fortan/586
D8: =E8&""&F8&""&G8&""&H8 -> ErgänzungsfuttermittelKatzeVitamin-Spurenelement-Präparat | E8: Ergänzungsfuttermittel | F8: Katze | G8: Vitamin-Spurenelement-Präparat | L8: ReConvales AntiPhos | M8: =BF8 -> 2 | N8: =BG8 -> 2.5 | P8: =BI8 -> 4.6 | R8: =BK8 -> 0.4 | S8: 900 | T8: 70 | U8: =IF(S8="","",S8/T8) -> 12.857143 | W8: 100 | X8: 120 | Z8: 1.15 | AB8: 0.7 | AC8: 10 | AF8: =AG8*$BO$13 -> 45 | AG8: 150 | AK8: 165 | AL8: =AK8*$BO$14 -> 4.125 | AN8: 6 | AO8: 0.5 | AP8: 0.75 | AS8: 6 | AY8: 40 | AZ8: 138 | BA8: 98.61 | BB8: 10 | BC8: ReConvales AntiPhos | BD8: Alfavet | BE8: Ergänzungsfuttermittel | BF8: 2 | BG8: 2.5 | BI8: 4.6 | BK8: 0.4 | BL8: Pflanzliche Nebenerzeugnisse, Fleisch und tierische Nebenerzeugnisse, Öle und Fette, Mineralstoffe (Calciumcarbonat 2,1 %), Hefen | BM8: https://www.vetena.de/Alfavet-ReConvales-AntiPhos-Hund-Katze
D9: =E9&""&F9&""&G9&""&H9 -> ErgänzungsfuttermittelKatzeVitamin-Spurenelement-Präparat | E9: Ergänzungsfuttermittel | F9: Katze | G9: Vitamin-Spurenelement-Präparat | L9: HepatoSan | M9: =BF9 -> 6 | N9: =BG9 -> 13.7 | P9: =BI9 -> 10.4 | R9: =BK9 -> 13.3 | U9: =IF(S9="","",S9/T9) | W9: 2 | X9: 170 | AE9: 800 | AF9: =AG9*$BO$13 -> 0 | AL9: =AK9*$BO$14 -> 0 | AN9: 240 | AP9: 28 | AR9: 16 | AS9: 800 | AW9: 400 | AY9: 960 | BA9: 266.25 | BB9: 0.7 | BC9: HepatoSan | BD9: Alfavet | BE9: Ergänzungsfuttermittel | BF9: 6 | BG9: 13.7 | BI9: 10.4 | BK9: 13.3 | BL9: Hefeerzeugnis 28 %, Mariendistelsamen 12,2 %, verarbeitetes tierisches Protein (Geflügelleber), Zichorien-Inulin 5 %, Monocalciumphosphat, Artischockenblätter 1,6 %, Kurkuma 0,8 %, Magnesiumstearat, Natriumchlorid, Magnesiumoxid | BM9: https://www.vetena.de/30-Tabletten-HepatoSan-700
D10: =E10&""&F10&""&G10&""&H10 -> ErgänzungsfuttermittelKatzeVitamin-Spurenelement-Präparat | E10: Ergänzungsfuttermittel | F10: Katze | G10: Vitamin-Spurenelement-Präparat | L10: Cervico | M10: =BF10 -> 6.9 | N10: =BG10 -> 47.8 | P10: =BI10 -> 3.9 | R10: =BK10 -> 1.7 | U10: =IF(S10="","",S10/T10) | AB10: 25 | AO10: 100 | AR10: 500 | AS10: 20000 | BA10: 38.78 | BB10: 1 | BC10: Cervico | BD10: Fortan | BE10: Ergänzungsfuttermittel | BF10: 6.9 | BG10: 47.8 | BI10: 3.9 | BK10: 1.7 | BL10: Hefen, MSM (Methyl Sulfonyl Methan) | BM10: https://fortan.de/Cervico/511
D11: =E11&""&F11&""&G11&""&H11 -> ErgänzungsfuttermittelKatzeVitamin-Spurenelement-Präparat | E11: Ergänzungsfuttermittel | F11: Katze | G11: Vitamin-Spurenelement-Präparat | L11: Animaux Gastro Balance for Cats | M11: =BF11 -> 14.3 | N11: =BG11 -> 32.1 | P11: =BI11 -> 12.1 | R11: =BK11 -> 5.8 | U11: =IF(S11="","",S11/T11) | W11: 1330 | X11: 1720 | Z11: 62.4 | AA11: 3.2 | AB11: 24 | AC11: 24 | AE11: 230 | AF11: =AG11*$BO$13 -> 1500 | AG11: 5000 | AK11: 500 | AL11: =AK11*$BO$14 -> 12.5 | AN11: 158 | AO11: 8.3 | AP11: 21.5 | AQ11: 17.8 | AR11: 139.3 | AS11: 353 | AT11: 90 | AU11: 45 | AV11: 3380 | AW11: 220 | AX11: 14.5 | BA11: 298.87 | BB11: 3.1 | BC11: animaux gastro balance for cats | BD11: animaux | BE11: Ergänzungsfuttermittel | BF11: 14.3 | BG11: 32.1 | BI11: 12.1 | BK11: 5.8 | BL11: Milch und Molkereierzeugnisse, Fleisch und tierische Nebenerzeugnisse, Obsttrester, Hefen, Zitronengras, Zichorienpülpe, Leinsaat, Mineralstoffe, Karottentrester, Reismehl, Natriumbikarbonat, Apfelpektin, Flohsamenschalen, Fenchelfrüchte, Eibischwurzel, Salbeiblätter, Kamillenblüten, Anissaat, Fisch und Fischnebenerzeugnisse. | BM11: https://animaux-nutrients.com/produkt/gastro-balance-for-cats/
D12: =E12&""&F12&""&G12&""&H12 -> ErgänzungsfuttermittelKatzeVitamin-Spurenelement-Präparat | E12: Ergänzungsfuttermittel | F12: Katze | G12: Vitamin-Spurenelement-Präparat | L12: Animaux Nutrients for Cats | M12: =BF12 -> 11.1 | N12: =BG12 -> 41.1 | P12: =BI12 -> 14.8 | R12: =BK12 -> 2.1 | U12: =IF(S12="","",S12/T12) | AA12: 12 | AB12: 90 | AC12: 90 | AE12: 860 | AF12: =AG12*$BO$13 -> 0 | AL12: =AK12*$BO$14 -> 0 | AO12: 32.5 | AP12: 84 | AQ12: 67 | AR12: 522 | AS12: 1320 | AT12: 340 | AU12: 200 | AV12: 12500 | AW12: 825 | BA12: 211.83 | BB12: 0.75 | BC12: animaux nutrients for cats | BD12: animaux | BE12: Ergänzungsfuttermittel | BF12: 11.1 | BG12: 41.1 | BI12: 14.8 | BK12: 2.1 | BL12: Erzeugnisse aus der Verarbeitung von Pflanzen, Mineralstoffe, DL-Methionin | BM12: https://www.vetena.de/120-Kautabletten-animaux-Nutrients-for-Cats
D13: =E13&""&F13&""&G13&""&H13 -> ErgänzungsfuttermittelKatzeVitamin-Spurenelement-Präparat | E13: Ergänzungsfuttermittel | F13: Katze | G13: Vitamin-Spurenelement-Präparat | L13: Multi-Mineral | M13: =BF13 -> 12.1 | N13: =BG13 -> 12.8 | P13: =BI13 -> 3.8 | R13: =BK13 -> 7.2 | S13: 2100 | T13: 400 | U13: =IF(S13="","",S13/T13) -> 5.25 | V13: 600 | X13: 200 | Z13: 120 | AA13: 40 | AB13: 200 | AC13: 50 | AD13: 1200 | AE13: 400 | AF13: =AG13*$BO$13 -> 3600 | AG13: 12000 | AK13: 1500 | AL13: =AK13*$BO$14 -> 37.5 | AN13: 80 | AO13: 12 | AP13: 6 | AQ13: 6 | AR13: 100 | AS13: 50 | AT13: 32 | AU13: 20 | AV13: 20000 | AW13: 200 | AY13: 40 | AZ13: 500 | BA13: 104.75 | BB13: 2 | BC13: Multi-Mineral | BD13: Vet-Concept | BE13: Ergänzungsfuttermittel | BF13: 12.1 | BG13: 12.8 | BI13: 3.8 | BK13: 7.2 | BL13: Kräuter* (Brennnessel, Fenchel, Anis, Kümmel, Birke, Island Moos), Apfelfaser, Bierhefe* , Calciumcarbonat, Petersilie* , Leinsamen, Karotten* , Seealgen* , Calciumglukonat, Magnesiumoxid, Magnesiumfumarat, Kaliumchlorid, * getrocknet | BM13: https://www.vet-concept.at/p/fuer-den-hund-multi-mineral-120g?d=1&emcs0=1&emcs1=Produktdetailseite&emcs2=null&emcs3=7062 | BN13: Faktor für Vitamin A | BO13: 0.3
D14: =E14&""&F14&""&G14&""&H14 -> ErgänzungsfuttermittelKatzeVitamin-Spurenelement-Präparat | E14: Ergänzungsfuttermittel | F14: Katze | G14: Vitamin-Spurenelement-Präparat | L14: VitalPro | M14: =BF14 -> 10 | N14: =BG14 -> 6.5 | P14: =BI14 -> 33.5 | R14: =BK14 -> 1 | U14: =IF(S14="","",S14/T14) | Z14: 7.5 | AB14: 15 | AC14: 0.4 | AF14: =AG14*$BO$13 -> 0 | AK14: 114.7 | AL14: =AK14*$BO$14 -> 2.8675 | AN14: 166 | AO14: 16 | AP14: 12 | AQ14: 8 | AR14: 56 | AS14: 179.9 | AT14: 93.7 | AU14: 15 | AV14: 1800 | AW14: 10 | AY14: 266 | AZ14: 200 | BA14: 171.82 | BB14: 6 | BC14: Vital Pro | BD14: Vet-Concept | BE14: Ergänzungsfuttermittel | BF14: 10 | BG14: 6.5 | BI14: 33.5 | BK14: 1 | BL14: Pflanzliche Nebenerzeugnisse, Öle und Fette (Leinöl 4 %), Fisch und Fischnebenerzeugnisse (Weißfischproteinkonzentrat 5 %), Fleisch und tierische Nebenerzeugnisse, Hefen (Quelle für Beta-Glucane, 1 %) | BM14: https://www.vet-concept.at/p/fuer-die-katze-vital-pro-110g-1 | BN14: Faktor für Vitamin D | BO14: 0.025
D15: =E15&""&F15&""&G15&""&H15 -> ErgänzungsfuttermittelKatzeVitamin-Spurenelement-Präparat | E15: Ergänzungsfuttermittel | F15: Katze | G15: Vitamin-Spurenelement-Präparat | L15: PETVITAL Arthro Tabletten | M15: =BF15 -> 6.4 | N15: =BG15 -> 2.3 | P15: =BI15 -> 0 | R15: =BK15 -> 14.7 | U15: =IF(S15="","",S15/T15) | Z15: 14.342 | AA15: 0.122 | AB15: 0.747 | AC15: 0.995 | AF15: =AG15*$BO$13 -> 0 | AL15: =AK15*$BO$14 -> 0 | AN15: 220.365 | AO15: 776.88 | AR15: 246.51 | BA15: 249.83 | BC15: PETVITAL Arthro Tabletten | BD15: Canina | BE15: Ergänzungsfuttermittel | BF15: 6.4 | BG15: 2.3 | BI15: 0 | BK15: 14.7 | BL15: Maltodextrin, Weidenrinde (Salix), Teufelskralle, Ingwer, Talkum, Magnesiumstearat, Kartoffelstärke | BM15: https://canina.de/products/723003-petvital-arthro-tabletten?cat_id=27
D16: =E16&""&F16&""&G16&""&H16 -> ErgänzungsfuttermittelKatzeVitamin-Spurenelement-Präparat | E16: Ergänzungsfuttermittel | F16: Katze | G16: Vitamin-Spurenelement-Präparat | L16: ReConvales Power Paste | M16: =BF16 -> 14 | N16: =BG16 -> 14 | P16: =BI16 -> 55 | R16: =BK16 -> 6 | U16: =IF(S16="","",S16/T16) | Z16: 10 | AB16: 10 | AC16: 6 | AF16: =AG16*$BO$13 -> 4050 | AG16: 13500 | AK16: 200 | AL16: =AK16*$BO$14 -> 5 | AN16: 120 | AO16: 25 | AP16: 3 | AQ16: 15 | AR16: 35 | AS16: 300 | AT16: 35 | AU16: 30 | AV16: 900 | AZ16: 500 | BA16: 108.27 | BC16: ReConvales Power Paste Hund und Katze | BD16: Alfavet | BE16: Ergänzungsfuttermittel | BF16: 14 | BG16: 14 | BI16: 55 | BK16: 6 | BL16: Öle und Fette, Hefen, Mineralstoffe | BM16: https://www.vetena.de/140-g-ReConvales-Power
D17: =E17&""&F17&""&G17&""&H17 -> ErgänzungsfuttermittelKatzeVitamin-Spurenelement-Präparat | E17: Ergänzungsfuttermittel | F17: Katze | G17: Vitamin-Spurenelement-Präparat | L17: Reconvales Energy | M17: =BF17 -> 2.7 | N17: =BG17 -> 17 | P17: =BI17 -> 15 | R17: =BK17 -> 1 | U17: =IF(S17="","",S17/T17) | Z17: 5 | AA17: 0.3 | AB17: 4.6 | AC17: 0.3 | AE17: 19 | AF17: =AG17*$BO$13 -> 60 | AG17: 200 | AK17: 16 | AL17: =AK17*$BO$14 -> 0.4 | AZ17: 200 | BA17: 110.15 | BB17: 40 | BC17: ReConvales Energy | BD17: Alfavet | BE17: Ergänzungsfuttermittel | BF17: 2.7 | BG17: 17 | BI17: 15 | BK17: 1 | BL17: Fleisch und tierische Nebenerzeugnisse, Öle und Fette, pflanzliche Nebenerzeugnisse, Mineralstoffe | BM17: https://www.vetena.de/180-ml-ReConvales-Energy
D18: =E18&""&F18&""&G18&""&H18 -> ErgänzungsfuttermittelKatzeVitamin-Spurenelement-Präparat | E18: Ergänzungsfuttermittel | F18: Katze | G18: Vitamin-Spurenelement-Präparat | L18: Natural Slim | M18: =BF18 -> 11 | N18: =BG18 -> 25 | P18: =BI18 -> 5.8 | R18: =BK18 -> 25 | S18: 2500 | T18: 1200 | U18: =IF(S18="","",S18/T18) -> 2.0833333 | V18: 110 | X18: 500 | Z18: 58 | AA18: 1.8 | AB18: 8.1 | AC18: 8.7 | AD18: 0.265 | AE18: 0.06 | AF18: =AG18*$BO$13 -> 315 | AG18: 1050 | AK18: 105 | AL18: =AK18*$BO$14 -> 2.625 | AN18: 10.5 | AO18: 0.35 | AP18: 0.7 | AQ18: 0.42 | AR18: 4.2 | AS18: 21 | AT18: 2.1 | AU18: 0.7 | AV18: 35 | AW18: 14 | BA18: 35.12 | BC18: Natural Slim | BD18: Vet-Concept | BE18: Ergänzungsfuttermittel | BF18: 11 | BG18: 25 | BI18: 5.8 | BK18: 25 | BL18: Trockenfleisch von Pute und Huhn, Karottenfaser, Apfelfaser, Cellulose, Orangenfaser, Kräuter, Schalentierextrakt, Guarana, Yucca schidigera | BM18: https://www.vet-concept.at/p/fuer-die-katze-natural-slim-400g-1200g
D19: =E19&""&F19&""&G19&""&H19 -> ErgänzungsfuttermittelKatzeVitamin-Spurenelement-Präparat | E19: Ergänzungsfuttermittel | F19: Katze | G19: Vitamin-Spurenelement-Präparat | L19: Dentes Cat | M19: =BF19 -> 31.5 | N19: =BG19 -> 18.6 | P19: =BI19 -> 11.8 | R19: =BK19 -> 1.9 | U19: =IF(S19="","",S19/T19) | AB19: 290 | AF19: =AG19*$BO$13 -> 0 | AL19: =AK19*$BO$14 -> 0 | AN19: 4000 | BA19: 825.7 | BB19: 1 | BC19: Dentes Cat | BD19: Nikolaus Nature | BE19: Ergänzungsfuttermittel | BF19: 31.5 | BG19: 18.6 | BI19: 11.8 | BK19: 1.9 | BL19: Omega-3-Fettsäuren (vegan), hydrolysiertes Kollagen, Plasmaprotein, Fischöl- und Fischknorpelpulver, Calciumcarbonat, Nachtkerzenölpulver (Gamma-Linolensäure), Karottenpulver, Grünlippmuschelpulver (Glukosaminsulfat, 90%ig), Katzenminze, Chondroitinsulfat (100%ig), Kieselerde, Zink-Acetat, Vitamin E (d-Alpha-Tocopherol), Zink (als Zinkchelat des Hydroxyanaloges von Methionin) | BM19: https://www.nikolaus-nature.com/produkte/dentes-cat-35g-pulver
D20: =E20&""&F20&""&G20&""&H20 -> ErgänzungsfuttermittelKatzeVitamin-Spurenelement-Präparat | E20: Ergänzungsfuttermittel | F20: Katze | G20: Vitamin-Spurenelement-Präparat | L20: Balance VMS | M20: =BF20 -> 88.2 | N20: =BG20 -> 0 | P20: =BI20 -> 5 | R20: =BK20 -> 0 | S20: 18300 | T20: 6700 | U20: =IF(S20="","",S20/T20) -> 2.7313433 | W20: 7500 | X20: 2000 | AA20: 12.5 | AF20: =AG20*$BO$13 -> 7500 | AG20: 25000 | AK20: 2500 | AL20: =AK20*$BO$14 -> 62.5 | AN20: 167.5 | AO20: 7.5 | AP20: 25 | AW20: 125 | AZ20: 2500 | BA20: 58.96 | BB20: 2.4 | BC20: Balance VMS | BD20: Trovet | BE20: Ergänzungsfuttermittel | BF20: 88.2 | BI20: 5 | BL20: Kalziumkarbonat, Monokalziumphosphat, Vitamine und Spurenelemente, Natriumchlorid, Magnesiumoxid, Maisöl | BM20: https://www.vetena.de/250-g-Balance-VMS
D21: =E21&""&F21&""&G21&""&H21 -> ErgänzungsfuttermittelKatzeVitamin-Spurenelement-Präparat | E21: Ergänzungsfuttermittel | F21: Katze | G21: Vitamin-Spurenelement-Präparat | L21: Fertil-Balance | M21: =BF21 -> 28.1 | N21: =BG21 -> 15 | P21: =BI21 -> 2 | R21: =BK21 -> 4.4 | S21: 6200 | T21: 2500 | U21: =IF(S21="","",S21/T21) -> 2.48 | V21: 900 | W21: 600 | X21: 1100 | Z21: 60 | AA21: 20 | AB21: 200 | AC21: 50 | AD21: 1000 | AE21: 500 | AF21: =AG21*$BO$13 -> 12000 | AG21: 40000 | AK21: 1000 | AL21: =AK21*$BO$14 -> 25 | AN21: 400 | AO21: 6 | AP21: 15 | AQ21: 6 | AR21: 200 | AS21: 100 | AT21: 40 | AU21: 40 | AV21: 4000 | AW21: 200 | AX21: 1 | AY21: 200 | AZ21: 1000 | BA21: 52.6 | BB21: 3 bis 9 | BC21: Fertil Balance | BD21: Vet-Concept | BE21: Ergänzungsfuttermittel | BF21: 28.1 | BG21: 15 | BI21: 2 | BK21: 4.4 | BL21: Johannisbrotmehl, Maiseiweiß, Dicalciumphosphat, Bananenmehl, Calciumcarbonat, Natriumchlorid, Magnesiumoxid, Apfelfaser, Sonnenblumenöl, Kaliumchlorid | BM21: https://www.vet-concept.at/p/fuer-die-katze-fertil-balance-500g
D22: =E22&""&F22&""&G22&""&H22 -> ErgänzungsfuttermittelKatzeVitamin-Spurenelement-Präparat | E22: Ergänzungsfuttermittel | F22: Katze | G22: Vitamin-Spurenelement-Präparat | L22: FeliMove urinary | M22: =BF22 -> 4.8 | N22: =BG22 -> 34.6 | P22: =BI22 -> 27.5 | R22: =BK22 -> 0.2 | S22: 100 | T22: 100 | U22: =IF(S22="","",S22/T22) -> 1 | W22: 100 | X22: 900 | Y22: 100 | AC22: 100 | AF22: =AG22*$BO$13 -> 0 | AL22: =AK22*$BO$14 -> 0 | AW22: 530 | BA22: 1276.6 | BB22: 0.2 | BC22: FeliMove urinary | BD22: FeliMove | BE22: Ergänzungsfuttermittel | BF22: 4.8 | BG22: 34.6 | BI22: 27.5 | BK22: 0.2 | BL22: Fischöl 53% (in Triglyceridform, davon mind. 50% EPA, 20% DHA), Chondroitinsulfat 26,6%, Cranberry-Extrakt 13,3%. Kapsel: Fischgelatine | BM22: https://fuerdeintier.de/fuer-deine-katze/felimove-urinary
D23: =E23&""&F23&""&G23&""&H23 -> ErgänzungsfuttermittelKatzeVitamin-Spurenelement-Präparat | E23: Ergänzungsfuttermittel | F23: Katze | G23: Vitamin-Spurenelement-Präparat | L23: Nutribound für Katzen | M23: =BF23 -> 1 | N23: =BG23 -> 2.7 | P23: =BI23 -> 1.9 | R23: =BK23 -> 0.8 | U23: =IF(S23="","",S23/T23) | Z23: 1.7 | AB23: 0.75 | AC23: 0.27 | AF23: =AG23*$BO$13 -> 126.36 | AG23: 421.2 | AK23: 15 | AL23: =AK23*$BO$14 -> 0.375 | AN23: 8.42 | AO23: 1.17 | AP23: 1.23 | AQ23: 2.23 | AS23: 14 | AY23: 56.1 | BA23: 70.09 | BB23: 6 | BC23: Nutribound für Katzen | BD23: Virbac | BE23: Ergänzungsfuttermittel | BF23: 1 | BG23: 2.7 | BI23: 1.9 | BK23: 0.8 | BL23: Fleisch und tierische Nebenerzeugnisse (Quellen für Arginin, Taurin und Glutamin (4.74 %), Pflanzliche Nebenprodukte, Öle und Fette (1.29 %), Mineralstoffe (0.69 %), Zichorieninulin (0.30 %), Fructooligosaccharide (0.11 %). | BM23: https://petshop.at.virbac.com/Nutribound-f%C3%BCr-Katzen?gad_source=1&gclid=Cj0KCQjwiYOxBhC5ARIsAIvdH51LqbcC0kxPvRuoWMXc206ZceO1L-QYajfvGvHFUozv1er-Y6-yMwkaAh3zEALw_wcB
D24: =E24&""&F24&""&G24&""&H24 -> ErgänzungsfuttermittelKatzeVitamin-Spurenelement-Präparat | E24: Ergänzungsfuttermittel | F24: Katze | G24: Vitamin-Spurenelement-Präparat | L24: Nutriplus | M24: =BF24 -> 2.3 | N24: =BG24 -> 1.2 | P24: =BI24 -> 30.9 | R24: =BK24 -> 2.2 | S24: 20 | T24: 4 | U24: =IF(S24="","",S24/T24) -> 5 | V24: 20 | W24: 60 | Z24: 9.24 | AC24: 18.3 | AF24: =AG24*$BO$13 -> 1.329 | AG24: 4.43 | AK24: 443 | AL24: =AK24*$BO$14 -> 11.075 | AQ24: 20 | AR24: 42 | AT24: 40 | BA24: 140.92 | BB24: 12 | BC24: Nutriplus | BD24: Virbac | BE24: Ergänzungsfuttermittel | BF24: 2.3 | BG24: 1.2 | BI24: 30.9 | BK24: 2.2 | BL24: Glucosesirup, Sojaöl, Fischöl, Zuckerrohrmelasse, hydrolysierte tierische Proteine (Schwein und Wiederkäuer), Magnesiumsulfat-Heptahydrat. | BM24: https://petshop.at.virbac.com/Nutri-plus-gel-2
D25: =E25&""&F25&""&G25&""&H25 -> ErgänzungsfuttermittelKatzeVitamin-Spurenelement-Präparat | E25: Ergänzungsfuttermittel | F25: Katze | G25: Vitamin-Spurenelement-Präparat | L25: Doppelherz Gelenk Complex | M25: =BF25 -> 4 | N25: =BG25 -> 5 | P25: =BI25 -> 5 | R25: =BK25 -> 1.5 | U25: =IF(S25="","",S25/T25) | AC25: 100 | AF25: =AG25*$BO$13 -> 0 | AL25: =AK25*$BO$14 -> 0 | AM25: 600 | BA25: 6796 | BB25: 10 | BC25: Doppelherz Gelenk Complex für Katzen | BD25: Doppelherz | BE25: Ergänzungsfuttermittel | BF25: 4 | BG25: 5 | BI25: 5 | BK25: 1.5 | BL25: Fleisch und tierische Nebenerzeugnisse, Öle und Fette (u. a. Lachsöl 3,9 %), Glucosamin (3,5 %), Grünlippmuschelmehl (2 %), Chondroitinsulfat (1 %), Milchprotein, Hagebuttenpulver (0,3 %) | BM25: https://www.fressnapf.at/p/doppelherz-gelenk-complex-fuer-katzen-25-stk-1376089/?utm_medium=public_affiliates&utm_source=awin&utm_campaign=at-go.kelkoogroup.net&utm_content=0&utm_placement=Vergleichsseiten&utm_term=503421-824C01J8FFTKRQ81RG93XX4C585HHB&sv1=affiliate&sv_campaign_id=503421&awc=68692_1727096771_5be8a3f2e7103ca495c264f3afb42d9b
D26: =E26&""&F26&""&G26&""&H26 -> ErgänzungsfuttermittelKatzeVitamin-Spurenelement-Präparat | E26: Ergänzungsfuttermittel | F26: Katze | G26: Vitamin-Spurenelement-Präparat | L26: Rena-Komplex | M26: =BF26 -> 25.3 | N26: =BG26 -> 13.1 | P26: =BI26 -> 3.6 | R26: =BK26 -> 9.1 | S26: 1200 | T26: 100 | U26: =IF(S26="","",S26/T26) -> 12 | V26: 100 | W26: 2100 | X26: 6500 | Z26: 300 | AB26: 400 | AE26: 2000 | AF26: =AG26*$BO$13 -> 36000 | AG26: 120000 | AL26: =AK26*$BO$14 -> 0 | AN26: 500 | AO26: 160 | AP26: 60 | AQ26: 60 | AV26: 200000 | AW26: 2000 | BA26: 69.5 | BB26: 1 bis 4 | BC26: Rena-Komplex | BD26: Vet-Concept | BE26: Diatergänzungsfuttermittel bei chronischer Niereninsuffizienz | BF26: 25.3 | BG26: 13.1 | BI26: 3.6 | BK26: 9.1 | BL26: Kräuter* (Weißdorn, Birke, Brennnessel) (40%), Reismehl, Natriumchlorid, Natriumhydrogencarbonat, Kaliumchlorid, Leinöl, *getrocknet | BM26: https://www.vet-concept.at/p/fuer-die-katze-rena-komplex-150g-500g
D27: =E27&""&F27&""&G27&""&H27 -> ErgänzungsfuttermittelKatzeVitamin-Spurenelement-Präparat | E27: Ergänzungsfuttermittel | F27: Katze | G27: Vitamin-Spurenelement-Präparat | L27: BARF Cat Plus | M27: =BF27 -> 12 | N27: =BG27 -> 12.9 | P27: =BI27 -> 3.7 | R27: =BK27 -> 6.9 | S27: 2000 | T27: 400 | U27: =IF(S27="","",S27/T27) -> 5 | V27: 600 | X27: 200 | Z27: 120 | AA27: 40 | AB27: 200 | AC27: 50 | AE27: 4000 | AF27: =AG27*$BO$13 -> 3600 | AG27: 12000 | AK27: 1500 | AL27: =AK27*$BO$14 -> 37.5 | AN27: 80 | AO27: 12 | AP27: 6 | AQ27: 6 | AR27: 100 | AS27: 50 | AT27: 32 | AU27: 20 | AV27: 20000 | AW27: 200 | AY27: 40 | AZ27: 500 | BA27: 82.5 | BC27: BARF Cat Plus | BD27: ANIBIO | BE27: Ergänzungsfuttermittel | BF27: 12 | BG27: 12.9 | BI27: 3.7 | BK27: 6.9 | BL27: Kräutermischung (Brennnessel, Fenchel, Anis, Kümmel, Island Moos), Apfeltrester, Bierhefe, Calciumcarbonat, Petersilie, Leinsamen, Karotten, Seealge, Calciumglukonat, Magnesiumoxid, Magnesiumfumarat, Kaliumchlorid. | BM27: https://www.anibio.de/katzen/barfen/barf-katze
D28: =E28&""&F28&""&G28&""&H28 -> ErgänzungsfuttermittelKatzeVitamin-Spurenelement-Präparat | E28: Ergänzungsfuttermittel | F28: Katze | G28: Vitamin-Spurenelement-Präparat | L28: Katze-Vital | M28: =BF28 -> 11.9 | N28: =BG28 -> 13.3 | P28: =BI28 -> 3.9 | R28: =BK28 -> 7.2 | S28: 2100 | T28: 400 | U28: =IF(S28="","",S28/T28) -> 5.25 | V28: 600 | X28: 200 | Z28: 120 | AA28: 40 | AB28: 200 | AC28: 50 | AE28: 4000 | AF28: =AG28*$BO$13 -> 3600 | AG28: 12000 | AK28: 1500 | AL28: =AK28*$BO$14 -> 37.5 | AN28: 80 | AO28: 12 | AP28: 6 | AQ28: 6 | AR28: 100 | AS28: 50 | AT28: 32 | AU28: 20 | AV28: 20000 | AW28: 200 | AY28: 40 | AZ28: 500 | BA28: 73.25 | BC28: Katze-Vital | BD28: ANIBIO | BE28: Ergänzungsfuttermittel | BF28: 11.9 | BG28: 13.3 | BI28: 3.9 | BK28: 7.2 | BL28: Kräutermischung (Brennnessel, Fenchel, Anis, Kümmel, Birke, Island Moos), Apfeltrester, Bierhefe, Calciumcarbonat, Petersilie, Leinsamen, Karotten, Seealge, Calciumglukonat, Magnesiumoxid, Magnesiumfumarat, Kaliumchlorid. | BM28: https://www.anibio.de/katzen/immunsystem-und-vitalitaet/katze-vital
D29: =E29&""&F29&""&G29&""&H29 -> ErgänzungsfuttermittelKatzeVitamin-Spurenelement-Präparat | E29: Ergänzungsfuttermittel | F29: Katze | G29: Vitamin-Spurenelement-Präparat | L29: Gelenkmix | M29: =BF29 -> 3.3 | N29: =BG29 -> 34.9 | P29: =BI29 -> 4.7 | R29: =BK29 -> 17.6 | U29: =IF(S29="","",S29/T29) | X29: 700 | AB29: 130 | AC29: 210 | AF29: =AG29*$BO$13 -> 0 | AL29: =AK29*$BO$14 -> 0 | AN29: 250 | AZ29: 1000 | BA29: 166.67 | BB29: 1 | BC29: Gelenkmix | BD29: nomsplus | BE29: Ergänzungsfuttermittel | BF29: 3.3 | BG29: 34.9 | BI29: 4.7 | BK29: 17.6 | BL29: Bierhefe (Saccharomyces Cerevisiae), Glucosamin 8,0%, Kurkumawurzel gemahlen 8,0%, Teufelskralle gemahlen 6,0%, Methylsulfonylmethan (MSM), Kohlensaurer Algenkalk, Gerstengras gemahlen 4,0%, Hyaluronsäure 1,0%, Hanföl | BM29: https://www.vetena.de/nomsplus-Gelenkmix-Hunde-Katzen
D30: =E30&""&F30&""&G30&""&H30 -> ErgänzungsfuttermittelKatzeVitamin-Spurenelement-Präparat | E30: Ergänzungsfuttermittel | F30: Katze | G30: Vitamin-Spurenelement-Präparat | L30: easy B.a.r.F basic | M30: =BF30 -> 38.5 | N30: =BG30 -> 5.2 | P30: =BI30 -> 0.6 | R30: =BK30 -> 0.2 | U30: =IF(S30="","",S30/T30) | V30: 1000 | X30: 12800 | Z30: 300 | AA30: 20 | AB30: 116 | AC30: 28 | AD30: 5600 | AF30: =AG30*$BO$13 -> 9090 | AG30: 30300 | AK30: 3030 | AL30: =AK30*$BO$14 -> 75.75 | AN30: 678 | AO30: 46.5 | AP30: 36.4 | AQ30: 32 | AR30: 303 | AS30: 1200 | AT30: 326 | AU30: 90 | AV30: 8400 | BA30: 110 | BB30: 1.25 | BC30: easy B.a.r.F basic | BD30: Lilly's Bar | BE30: Ergänzungsfuttermittel | BF30: 38.5 | BG30: 5.2 | BI30: 0.6 | BK30: 0.2 | BL30: Pektine, Mineralstoffe und Vitamine | BM30: https://www.barf-kultur.de/easy-BarF-basic
D31: =E31&""&F31&""&G31&""&H31 -> ErgänzungsfuttermittelKatzeVitamin-Spurenelement-Präparat | E31: Ergänzungsfuttermittel | F31: Katze | G31: Vitamin-Spurenelement-Präparat | L31: Enterogelan 10 | M31: =BF31 -> 35 | N31: =BG31 -> 0 | P31: =BI31 -> 0 | R31: =BK31 -> 0 | U31: =IF(S31="","",S31/T31) | W31: 800 | X31: 2000 | Y31: 3500 | AF31: =AG31*$BO$13 -> 0 | AL31: =AK31*$BO$14 -> 0 | AR31: 10 | BA31: 1390 | BC31: Enterogelan 10 | BD31: Virbac | BE31: Ergänzungsfuttermittel | BF31: 35 | BG31: 0 | BI31: 0 | BJ31: =100-(BF31+BG31+BI31) -> 65 | BK31: 0 | BL31: Leicht verdauliche Kohlenhydrate (Dextrose). Inulin, Trockengrünfutter (Kamille, Heidelbeere, Pfefferminze, Eiche, Melisse, Koriander, Kümmel, Fenchel), Natriumchlorid, Magnesiumcitrat, Kaliumsorbat, Kaliumchlorid | BM31: https://petshop.at.virbac.com/Enterogelan-10-2
D32: =E32&""&F32&""&G32&""&H32 -> ErgänzungsfuttermittelKatzeVitamin-Spurenelement-Präparat | E32: Ergänzungsfuttermittel | F32: Katze | G32: Vitamin-Spurenelement-Präparat | L32: CystoCalm | M32: =BF32 -> 7.5 | N32: =BG32 -> 26.9 | P32: =BI32 -> 8.1 | R32: =BK32 -> 0.7 | U32: =IF(S32="","",S32/T32) | AB32: 400 | AF32: =AG32*$BO$13 -> 0 | AL32: =AK32*$BO$14 -> 0 | AO32: 2500 | BB32: 2 | BC32: CystoCalm | BD32: Almapharm | BE32: Ergänzungsfuttermittel | BF32: 7.5 | BG32: 26.9 | BI32: 8.1 | BK32: 0.7 | BL32: Kartoffelstärke, Glukosamin, Kürbiskerne, Hühnreleber, Chondroitinsulfat, Milchprotein-Hydrolysat, Hyaluronsäure | BM32: https://www.almapharm.de/produkt/cystocalm-120g/
D33: =E33&""&F33&""&G33&""&H33 -> ErgänzungsfuttermittelKatzeVitamin-Spurenelement-Präparat | E33: Ergänzungsfuttermittel | F33: Katze | G33: Vitamin-Spurenelement-Präparat | L33: Calo-Pet Gel | M33: =BF33 -> 0.3 | N33: =BG33 -> 0.5 | P33: =BI33 -> 27.5 | R33: =BK33 -> 5.2 | U33: =IF(S33="","",S33/T33) | Z33: 9.5 | AC33: 17 | AD33: 8500 | AF33: =AG33*$BO$13 -> 4050 | AG33: 13500 | AK33: 1000 | AL33: =AK33*$BO$14 -> 25 | AN33: 90 | AO33: 28 | AP33: 0.2 | AQ33: 13 | AR33: 33 | BA33: 95.5 | BB33: 6 | BC33: Calo-Pet Gel | BD33: Vetoquinol | BE33: Ergänzungsfuttermittel | BF33: 0.3 | BG33: 0.5 | BI33: 27.5 | BK33: 5.2 | BL33: Glucosesirup, Sojaöl, Malz, Fischöl, Zuckerrohrmelasse, Magnesiumsulfat-Heptahydrat, leicht verdauliche Inhaltsstoffe: Glucosesirup, Malz, Zuckerrohrmelasse. | BM33: https://vetoquinol.at/produkte/calo-pet-gel
D34: =E34&""&F34&""&G34&""&H34 -> ErgänzungsfuttermittelKatzeVitamin-Spurenelement-Präparat | E34: Ergänzungsfuttermittel | F34: Katze | G34: Vitamin-Spurenelement-Präparat | L34: GimCat Multivitamin Extra | M34: =BF34 -> 5.5 | N34: =BG34 -> 5 | P34: =BI34 -> 36.5 | R34: =BK34 -> 2.5 | U34: =IF(S34="","",S34/T34) | AB34: 9.9 | AF34: =AG34*$BO$13 -> 0 | AK34: 114.7 | AL34: =AK34*$BO$14 -> 2.8675 | AN34: 166 | AO34: 2.7 | AP34: 2 | AQ34: 1.3 | AR34: 9.3 | AS34: 179.9 | AT34: 93.7 | AU34: 15 | AV34: 18000 | AX34: 0.1 | AY34: 266 | AZ34: 200 | BA34: 44.95 | BB34: 3 | BC34: GimCat Multi-Vitamin-Extra Katzenpaste 200g | BD34: GimCat | BE34: Ergänzungsfuttermittel | BF34: 5.5 | BG34: 5 | BI34: 36.5 | BK34: 2.5 | BL34: pflanzliche Nebenerzeugnisse, Öle und Fette (Fischöl 8,0%), Hefen (enthält 1,0% Beta-Glucan)Ohne Zusatz von Zucker | BM34: https://www.fressnapf.at/p/gimcat-multi-vitamin-extra-katzenpaste-200-g-1084660002/
D35: =E35&""&F35&""&G35&""&H35 -> ErgänzungsfuttermittelKatzeVitamin-Spurenelement-Präparat | E35: Ergänzungsfuttermittel | F35: Katze | G35: Vitamin-Spurenelement-Präparat | L35: Coxan Cat | M35: =BF35 -> 14 | N35: =BG35 -> 23 | P35: =BI35 -> 15.5 | R35: =BK35 -> 1.5 | U35: =IF(S35="","",S35/T35) | AB35: 300 | AF35: =AG35*$BO$13 -> 0 | AL35: =AK35*$BO$14 -> 0 | AN35: 5000 | BA35: 662.5 | BB35: 0.9 | BC35: Coxan Cat | BD35: Nikolaus Nature | BE35: Ergänzungsfuttermittel | BF35: 14 | BG35: 23 | BI35: 15.5 | BK35: 1.5 | BL35: Omega-3-Fettsäuren (vegan), Plasmaprotein, Grünlippmuschelpulver (Glukosaminsulfat, 90%ig), Fischknorpelpulver, Nachtkerzenölpulver (Gamma-Linolensäure), Chondroitinsulfat (100%ig), Karottenpulver, Katzenminze, Vitamin E (d-Alpha-Tocopherol), Zink (als Zinkchelat des Hydroxyanaloges von Methionin) | BM35: https://www.nikolaus-nature.com/produkte/coxan-cat-40g-pulver
D36: =E36&""&F36&""&G36&""&H36 -> ErgänzungsfuttermittelKatzeVitamin-Spurenelement-Präparat | E36: Ergänzungsfuttermittel | F36: Katze | G36: Vitamin-Spurenelement-Präparat | L36: IMUN Cat Para | M36: =BF36 -> 13 | N36: =BG36 -> 22 | P36: =BI36 -> 16 | R36: =BK36 -> 6.5 | U36: =IF(S36="","",S36/T36) | AB36: 350 | AF36: =AG36*$BO$13 -> 0 | AL36: =AK36*$BO$14 -> 0 | AN36: 1150 | BA36: 765.7 | BB36: 0.8 | BC36: Imun Cat Para | BD36: Nikolaus Nature | BE36: Ergänzungsfuttermittel | BF36: 13 | BG36: 22 | BI36: 16 | BK36: 6.5 | BL36: Plasmaprotein, Karottenpulver, Trockenalgen (Schizochytrium sp.), Schwarzkümmelkuchen, Chitosan/Chitin (aus Weich- und Krebstieren), Calciumcarbonat, Katzenkralle (Uncaria tomentosa), Neem-Extrakt, Nachtkerzenölpulver (Gamma-Linolensäure), Katzenminze, natürliches Vitamin B aus Buchweizenkeimling, Vitamin E (d-Alpha-Tocopherol), Zink (als Zinkchelat des Hydroxyanaloges von Methionin) | BM36: https://www.nikolaus-nature.com/produkte/imun-cat-para-35g-pulver
D37: =E37&""&F37&""&G37&""&H37 -> ErgänzungsfuttermittelKatzeVitamin-Spurenelement-Präparat | E37: Ergänzungsfuttermittel | F37: Katze | G37: Vitamin-Spurenelement-Präparat | L37: IMUN Cat | M37: =BF37 -> 13 | N37: =BG37 -> 22 | P37: =BI37 -> 16 | R37: =BK37 -> 6.5 | U37: =IF(S37="","",S37/T37) | AB37: 340 | AF37: =AG37*$BO$13 -> 0 | AL37: =AK37*$BO$14 -> 0 | AN37: 1100 | BA37: 622 | BB37: 1.2 | BC37: Imun Cat | BD37: Nikolaus Nature | BE37: Ergänzungsfuttermittel | BF37: 13 | BG37: 22 | BI37: 16 | BK37: 6.5 | BL37: Omega-3-Fettsäuren (vegan), Plasmaprotein, Chitosan/Chitin (aus Weich- und Krebstieren), Katzenkralle (Uncaria tomentosa), Schwarzkümmelkuchen, Neem-Extrakt, Nachtkerzenölpulver (Gamma-Linolensäure), Calciumcarbonat, Katzenminze, natürliches Vitamin B aus Buchweizenkeimling, Vitamin E (d-Alpha-Tocopherol), Zink (als Zinkchelat des Hydroxyanaloges von Methionin) | BM37: https://www.nikolaus-nature.com/produkte/imun-cat-50g-pulver
D38: =E38&""&F38&""&G38&""&H38 -> ErgänzungsfuttermittelKatzeVitamin-Spurenelement-Präparat | E38: Ergänzungsfuttermittel | F38: Katze | G38: Vitamin-Spurenelement-Präparat | L38: Annimally Haut und Fell | M38: =BF38 -> 10.4 | N38: =BG38 -> 38.2 | P38: =BI38 -> 7.8 | R38: =BK38 -> 0.6 | U38: =IF(S38="","",S38/T38) | AB38: 390 | AF38: =AG38*$BO$13 -> 15000 | AG38: 50000 | AL38: =AK38*$BO$14 -> 0 | AN38: 200 | AO38: 980 | AP38: 320 | AQ38: 84 | AR38: 5200 | AS38: 107800 | AT38: 10 | AU38: 2.5 | AV38: 600 | AW38: 1000 | AZ38: 6400 | BA38: 157.5 | BB38: 1.5 | BC38: Haut und Fell Pulver | BD38: Annimally | BE38: Ergänzungsfuttermittel | BF38: 10.4 | BG38: 38.2 | BI38: 7.8 | BK38: 0.6 | BL38: Hefe (inaktive Saccharomyces Cerevisae); 7 % Fischöl aus Sardinen, microverkapselt; 5 % Methylsulfonylmethan (MSM); 5 % Spirulina; Borretschöl; 2 % Nachtkerzenöl; Brennnesselblätter Feinschnitt | BM38: https://www.annimally.at/products/haut-fell-pulver-pflege-hund-katze?_gl=1*12sxr8s*_up*MQ..&gclid=Cj0KCQjwo8S3BhDeARIsAFRmkOOkVlIfv6XQGMfHY9rb7s7ecTJjkN20Gmvh4Y3s66WGsIlr4ZT4mcsaAnwnEALw_wcB
D39: =E39&""&F39&""&G39&""&H39 -> ErgänzungsfuttermittelKatzeVitamin-Spurenelement-Präparat | E39: Ergänzungsfuttermittel | F39: Katze | G39: Vitamin-Spurenelement-Präparat | L39: Annimally Gelenk Komplex | M39: =BF39 -> 7.5 | N39: =BG39 -> 46 | P39: =BI39 -> 4 | R39: =BK39 -> 0.4 | U39: =IF(S39="","",S39/T39) | AA39: 120 | AB39: 130 | AC39: 210 | AF39: =AG39*$BO$13 -> 0 | AL39: =AK39*$BO$14 -> 0 | AN39: 500 | AZ39: 3440 | BA39: 182.5 | BB39: 1 | BC39: Gelenk Komplex | BD39: Annimally | BE39: Ergänzungsfuttermittel | BF39: 7.5 | BG39: 46 | BI39: 4 | BK39: 0.4 | BL39: Hefe (inaktive Saccharomyces Cerevisae); 22 % Grünlippmuschelfleischmehl getr.; 7% Gelatine von Schweinen; 5,5 % Glucosamin-Hydrochlorid; 4,5 % Teufelskrallenwurzel gemahlen; 3 % Methylsulfonylmethan (MSM); 2,8 % Chondroitin-Sulfat (Schwein); 1,7 % Curcumawurzel gemahlen | BM39: https://www.annimally.at/products/gruenlippmuschel-pulver-katze?_gl=1*13htxg2*_up*MQ..&gclid=Cj0KCQjwo8S3BhDeARIsAFRmkOOkVlIfv6XQGMfHY9rb7s7ecTJjkN20Gmvh4Y3s66WGsIlr4ZT4mcsaAnwnEALw_wcB
D40: =E40&""&F40&""&G40&""&H40 -> ErgänzungsfuttermittelKatzeVitamin-Spurenelement-Präparat | E40: Ergänzungsfuttermittel | F40: Katze | G40: Vitamin-Spurenelement-Präparat | L40: Annimally Vitamin B Komplex | M40: =BF40 -> 25.5 | N40: =BG40 -> 29.3 | P40: =BI40 -> 2.8 | R40: =BK40 -> 1.7 | U40: =IF(S40="","",S40/T40) | AE40: 45 | AF40: =AG40*$BO$13 -> 0 | AL40: =AK40*$BO$14 -> 0 | AO40: 4500 | AP40: 1450 | AQ40: 1350 | AR40: 24000 | AT40: 45 | AU40: 12 | AV40: 2800 | AX40: 2 | BC40: Vitamin B Komplex | BD40: Annimally | BE40: Ergänzungsfuttermittel | BF40: 25.5 | BG40: 29.3 | BI40: 2.8 | BK40: 1.7 | BL40: 45 % Bierhefe (inaktiv), Apfelfaser (getrocknet), Rapsöl (gehärtet) | BM40: https://www.annimally.at/products/vitamin-b-hund-katze?_gl=1*mhpp7l*_up*MQ..&gclid=Cj0KCQjwo8S3BhDeARIsAFRmkOOkVlIfv6XQGMfHY9rb7s7ecTJjkN20Gmvh4Y3s66WGsIlr4ZT4mcsaAnwnEALw_wcB
...

Sheet Einzelfuttermittel
M1: Ra | N1: Rp | O1: vRp | P1: Rfe | Q1: NfE | R1: Rfa | S1: Ca | T1: P | V1: Mg | W1: K | X1: Na | Y1: Cl | Z1: Fe | AA1: Cu | AB1: Zn | AC1: Mn | AD1: Jod | AE1: Selen | AG1: Vit. A | AI1: b-Carotinoide | AL1: Vit. D3 | AN1: Vit. E | AO1: Vit. B1 | AP1: Vit. B2 | AQ1: Vit. B6 | AR1: Vit. B12 | AS1: Biotin | AT1: Niacin | AU1: Pantothensäure | AV1: Folsäure | AW1: Vit C | AX1: Vit K | AY1: Cholin
D2: 1 | E2: 2 | F2: 3 | G2: 4 | H2: 5 | I2: 6 | J2: 7 | K2: 8 | L2: 9 | M2: 14 | N2: 15 | O2: 16 | P2: 17 | Q2: 18 | R2: 19 | S2: 64 | T2: 65 | V2: 66 | W2: 67 | X2: 68 | Y2: 69 | Z2: 70 | AA2: 71 | AB2: 72 | AC2: 73 | AD2: 74 | AE2: 75 | AF2: 76 | AG2: 77 | AH2: 78 | AI2: 79 | AJ2: 80 | AK2: 81 | AL2: 82 | AM2: 83 | AN2: 84 | AO2: 85 | AP2: 86 | AQ2: 87 | AR2: 88 | AS2: 89 | AT2: 90 | AU2: 91 | AV2: 92 | AW2: 93 | AX2: 94 | AY2: 95 | BA2: 96 | BC2: 97 | BD2: 98 | BE2: 99 | BF2: 100 | BG2: 101 | BH2: 102 | BI2: 103 | BJ2: 104 | BK2: 105 | BL2: 106
D3: Identifier | E3: Typ | F3: Spezies | G3: Kategorie | H3: Nummer fortlaufend in Kategorie | I3: Nummer fortlaufend | J3: Kategorie-Nummer | K3: Anfangsbuchstabe | L3: Futtermittel | M3: Ra [g]/[100g] | N3: Rp [g]/[100g] | O3: vRp [g]/[100g] | P3: Rfe [g]/[100g] | Q3: NfE [g]/[100g] | R3: Rfa [g]/[100g] | S3: Ca [mg]/[100g] | T3: P [mg]/[100g] | U3: Ca/P-Verhältnis | V3: Mg [mg]/[100g] | W3: K [mg]/[100g] | X3: Na [mg]/[100g] | Y3: Cl [mg]/[100g] | Z3: Fe [mg]/[100g] | AA3: Cu [mg]/[100g] | AB3: Zn [mg]/[100g] | AC3: Mn [mg]/[100g] | AD3: Jod [µg]/[100g] | AE3: Selen [µg]/[100g] | AF3: Vit. A [µg]/[100g] | AG3: Vit. A [IE]/[100g] | AH3: Retinoläquivalent [µg]/[100g] | AI3: b-Carotinoide [µg]/[100g] | AJ3: alle Carotinoide [µg]/[100g] | AK3: Vit. D3 [IE]/[100g] | AL3: Vit. D3 [µg]/[100g] | AM3: Vit E activity [mg]/[100g] | AN3: Vit. E (a-Tocopherol) [mg]/[100g] | AO3: Vit. B1 [mg]/[100g] | AP3: Vit. B2 [mg]/[100g] | AQ3: Vit. B6 [mg]/[100g] | AR3: Vit. B12 [µg]/[100g] | AS3: Biotin [µg]/[100g] | AT3: Niacin [mg]/[100g] | AU3: Pantothensäure [mg]/[100g] | AV3: Folsäure [µg]/[100g] | AW3: Vit C [mg]/[100g] | AX3: Vit K [mg]/[100g] | AY3: Cholin [mg]/[100g] | AZ3: Taurin [mg]/[100 g] | BA3: Preis (€) pro kg | BB3: Empfolene Dosierung (g pro Tag) | BC3: Name komplett | BD3: Marke | BE3: Produkt (bei Fertigfutter) | BF3: Ra [%TS] | BG3: Rp [%TS] | BI3: Rfe [%TS] | BJ3: NfE [%TS] | BK3: Rfa [%TS] | BL3: bei Fertigfutter: Zusammensetzung | BM3: Links
D4: =E4&""&F4&""&G4&""&H4 -> EinzelfuttermittelKatzeInnereien, TNPs, Schlachtabfälle und Tiermehle | E4: Einzelfuttermittel | F4: Katze | G4: Innereien, TNPs, Schlachtabfälle und Tiermehle | L4: Blutmehl | M4: =BF4 -> 0 | N4: =BG4 -> 92 | P4: =BI4 -> 0 | R4: =BK4 -> 0 | U4: =IF(S4="","",S4/T4) | Z4: 280 | BA4: 58 | BB4: 1.25 | BC4: Fortain | BD4: Fortan | BE4: Einzelfuttermittel | BG4: 92 | BL4: Hämoglobin vom Schwein | BM4: https://www.barf-kultur.de/Fortain
D5: =E5&""&F5&""&G5&""&H5 -> EinzelfuttermittelKatzeGemüse, Obst und Faserstoffe | E5: Einzelfuttermittel | F5: Katze | G5: Gemüse, Obst und Faserstoffe | L5: Pulvercellulose | M5: =BF5 -> 0 | N5: =BG5 -> 0 | P5: =BI5 -> 0 | R5: =BK5 -> 98.8 | U5: =IF(S5="","",S5/T5) | BA5: 12.38 | BB5: 0.75 | BC5: Futterzellulose | BD5: BARF Kultur | BE5: Einzelfuttermittel | BK5: 98.8 | BL5: 100 % Pulverzellulose | BM5: https://www.barf-kultur.de/Futterzellulose
D6: =E6&""&F6&""&G6&""&H6 -> EinzelfuttermittelKatzeInnereien, TNPs, Schlachtabfälle und Tiermehle | E6: Einzelfuttermittel | F6: Katze | G6: Innereien, TNPs, Schlachtabfälle und Tiermehle | L6: Blutmehl | M6: =BF6 -> 0 | N6: =BG6 -> 92 | P6: =BI6 -> 0 | R6: =BK6 -> 0 | U6: =IF(S6="","",S6/T6) | BA6: 27.6 | BB6: 1.2 | BC6: Rinderblutpulver | BD6: BARF Kultur | BE6: Einzelfuttermittel | BG6: 92 | BL6: Rinderblut (Vollblut vom Rind, getrocknet) | BM6: https://www.barf-kultur.de/Rinderblutpulver
D7: =E7&""&F7&""&G7&""&H7 -> EinzelfuttermittelKatzeFleisch-, Fisch- und Algenprodukte | E7: Einzelfuttermittel | F7: Katze | G7: Fleisch-, Fisch- und Algenprodukte | L7: Algenöl | M7: =BF7 -> 0 | N7: =BG7 -> 0 | P7: =BI7 -> 0 | R7: =BK7 -> 0 | U7: =IF(S7="","",S7/T7) | BA7: 754.55 | BC7: Algenöl Kapsel | BD7: BARF Kultur | BE7: Einzelfuttermittel | BL7: Öl aus der Mikroalge Schizochytrium sp., pflanzliche Kapselhülle (Glycerin, Maisstärke, Algen-Carrageen, Natriumcarbonat) | BM7: https://www.barf-kultur.de/Algenoel-Kapseln
D8: =E8&""&F8&""&G8&""&H8 -> EinzelfuttermittelKatzeGemüse, Obst und Faserstoffe | E8: Einzelfuttermittel | F8: Katze | G8: Gemüse, Obst und Faserstoffe | L8: Apfelessig | M8: =BF8 -> 0.8 | N8: =BG8 -> 0.4 | P8: =BI8 -> 0 | R8: =BK8 -> 0 | U8: =IF(S8="","",S8/T8) | BA8: 15.8 | BC8: Bio Apfelessig | BD8: BARF Kultur | BE8: Einzelfuttermittel | BF8: 0.8 | BG8: 0.4 | BI8: 0 | BK8: 0 | BL8: 100% Apfelessig, naturtrüb (mind. 5% Säure) | BM8: https://www.barf-kultur.de/Bio-Apfelessig
D9: =E9&""&F9&""&G9&""&H9 -> EinzelfuttermittelKatzeFleisch-, Fisch- und Algenprodukte | E9: Einzelfuttermittel | F9: Katze | G9: Fleisch-, Fisch- und Algenprodukte | L9: Lithothamnium | M9: =BF9 -> 0 | N9: =BG9 -> 0 | P9: =BI9 -> 0 | R9: =BK9 -> 0 | S9: 29600 | T9: 200 | U9: =IF(S9="","",S9/T9) -> 148 | BA9: 21 | BC9: Algenkalk | BD9: BARF Kultur | BE9: Einzelfuttermittel | BL9: 100% Algenkalk (Lithothamnium calcareum), pulverisiert | BM9: https://www.barf-kultur.de/Algenkalk
D10: =E10&""&F10&""&G10&""&H10 -> EinzelfuttermittelKatzeEi- und Milchprodukte | E10: Einzelfuttermittel | F10: Katze | G10: Ei- und Milchprodukte | L10: Eierschalen, getrocknet | M10: =BF10 -> 95.5 | N10: =BG10 -> 0 | P10: =BI10 -> 0 | R10: =BK10 -> 0 | S10: 38200 | T10: 100 | U10: =IF(S10="","",S10/T10) -> 382 | BA10: 34.4 | BC10: BIO Eierschalenpulver | BD10: BARF Kultur | BE10: Einzelfuttermittel | BF10: 95.5 | BL10: 100% Bio Eierschalen, gemahlen | BM10: https://www.barf-kultur.de/Bio-Eierschalenpulver
D11: =E11&""&F11&""&G11&""&H11 -> EinzelfuttermittelKatzeMineralstoffe | E11: Einzelfuttermittel | F11: Katze | G11: Mineralstoffe | L11: Dicalciumphosphat | M11: =BF11 -> 0 | N11: =BG11 -> 0 | P11: =BI11 -> 0 | R11: =BK11 -> 0 | S11: 29000 | T11: 22000 | U11: =IF(S11="","",S11/T11) -> 1.3181818 | Y11: 90 | BA11: 36.25 | BC11: Dicalciumphosphat | BD11: BARF Kultur | BE11: Einzelfuttermittel | BL11: 100% Dicalciumphosphat, pulverisiert | BM11: https://www.barf-kultur.de/Dicalciumphosphat
D12: =E12&""&F12&""&G12&""&H12 -> EinzelfuttermittelKatzeFleisch-, Fisch- und Algenprodukte | E12: Einzelfuttermittel | F12: Katze | G12: Fleisch-, Fisch- und Algenprodukte | L12: Algen, getrocknet | M12: =BF12 -> 5.2 | N12: =BG12 -> 63 | P12: =BI12 -> 10.1 | R12: =BK12 -> 0 | U12: =IF(S12="","",S12/T12) | BA12: 106 | BB12: 1 | BC12: Bio Chlorella | BD12: BARF Kultur | BE12: Einzelfuttermittel | BF12: 5.2 | BG12: 63 | BI12: 10.1 | BL12: 100 % Chlorella vulgaris | BM12: https://www.barf-kultur.de/Bio-Chlorella
D13: =E13&""&F13&""&G13&""&H13 -> EinzelfuttermittelKatzeGemüse, Obst und Faserstoffe | E13: Einzelfuttermittel | F13: Katze | G13: Gemüse, Obst und Faserstoffe | L13: Cranberrypulver | M13: =BF13 -> 0 | N13: =BG13 -> 0 | P13: =BI13 -> 11.9 | R13: =BK13 -> 14.2 | U13: =IF(S13="","",S13/T13) | BA13: 149 | BB13: 1.5 | BC13: Bio Cranberrypulver | BD13: BARF Kultur | BE13: Einzelfuttermittel | BI13: 11.9 | BK13: 14.2 | BL13: 100 % Bio Cranberrys, gefriergetrocknet und gemahlen | BM13: https://www.barf-kultur.de/Bio-Cranberrypulver
D14: =E14&""&F14&""&G14&""&H14 -> EinzelfuttermittelKatzeGemüse, Obst und Faserstoffe | E14: Einzelfuttermittel | F14: Katze | G14: Gemüse, Obst und Faserstoffe | L14: Hagebuttenpulver | M14: =BF14 -> 0 | N14: =BG14 -> 8.7 | P14: =BI14 -> 0.8 | R14: =BK14 -> 4.6 | U14: =IF(S14="","",S14/T14) | BA14: 37.33 | BC14: Bio Hagebuttenschalen | BD14: BARF Kultur | BE14: Einzelfuttermittel | BG14: 8.7 | BI14: 0.8 | BK14: 4.6 | BL14: 100% Bio Rosa canina, pulverisiert | BM14: https://www.barf-kultur.de/Bio-Hagebuttenschalen
D15: =E15&""&F15&""&G15&""&H15 -> EinzelfuttermittelKatzeFleisch-, Fisch- und Algenprodukte | E15: Einzelfuttermittel | F15: Katze | G15: Fleisch-, Fisch- und Algenprodukte | L15: Seealgenmehl | M15: =BF15 -> 19 | N15: =BG15 -> 9.6 | P15: =BI15 -> 3.1 | R15: =BK15 -> 4.6 | U15: =IF(S15="","",S15/T15) | AD15: 73100 | BA15: 16.75 | BC15: Bio Seealgenmehl | BD15: BARF Kultur | BE15: Einzelfuttermittel | BF15: 19 | BG15: 9.6 | BI15: 3.1 | BK15: 4.6 | BL15: 100% Bio Ascophyllum Nodosum | BM15: https://www.barf-kultur.de/Bio-Seealgenmehl
D16: =E16&""&F16&""&G16&""&H16 -> EinzelfuttermittelKatzeFleisch-, Fisch- und Algenprodukte | E16: Einzelfuttermittel | F16: Katze | G16: Fleisch-, Fisch- und Algenprodukte | L16: Algen, getrocknet | M16: =BF16 -> 9.8 | N16: =BG16 -> 69.8 | P16: =BI16 -> 5.7 | R16: =BK16 -> 0.3 | U16: =IF(S16="","",S16/T16) | BA16: 71.6 | BB16: 1 | BC16: Bio Spirulina | BD16: BARF Kultur | BE16: Einzelfuttermittel | BF16: 9.8 | BG16: 69.8 | BI16: 5.7 | BK16: 0.3 | BL16: 100% Bio Spirulina platensis | BM16: https://www.barf-kultur.de/Bio-Spirulina
D17: =E17&""&F17&""&G17&""&H17 -> EinzelfuttermittelKatzeFleisch-, Fisch- und Algenprodukte | E17: Einzelfuttermittel | F17: Katze | G17: Fleisch-, Fisch- und Algenprodukte | L17: Algen, getrocknet | M17: =BF17 -> 6.7 | N17: =BG17 -> 65.9 | P17: =BI17 -> 6.6 | R17: =BK17 -> 0 | U17: =IF(S17="","",S17/T17) | BA17: 72.67 | BC17: Spirulina Tabs | BD17: BARF Kultur | BE17: Einzelfuttermittel | BF17: 6.7 | BG17: 65.9 | BI17: 6.6 | BL17: 100% Spirulina platensis, gepresst zu Tabletten | BM17: https://www.barf-kultur.de/Bio-Spirulina-Tabs
D18: =E18&""&F18&""&G18&""&H18 -> EinzelfuttermittelKatzeGemüse, Obst und Faserstoffe | E18: Einzelfuttermittel | F18: Katze | G18: Gemüse, Obst und Faserstoffe | L18: Hefen, inaktiviert | M18: =BF18 -> 8 | N18: =BG18 -> 46 | P18: =BI18 -> 2.7 | R18: =BK18 -> 1 | S18: 200 | T18: 1400 | U18: =IF(S18="","",S18/T18) -> 0.14285714 | V18: 200 | X18: 200 | Z18: 48 | AA18: 6 | AB18: 10 | AC18: 5 | AO18: 12.5 | AP18: 4.5 | AQ18: 4.5 | AS18: 85 | AV18: 1800 | BA18: 19 | BB18: 1 | BC18: Bierhefe | BD18: BARF Kultur | BE18: Einzelfuttermittel | BF18: 8 | BG18: 46 | BI18: 2.7 | BK18: 1 | BL18: 100% Saccharomyces cerevisiae, pulverisiert | BM18: https://www.barf-kultur.de/Bierhefe
D19: =E19&""&F19&""&G19&""&H19 -> EinzelfuttermittelKatzeGemüse, Obst und Faserstoffe | E19: Einzelfuttermittel | F19: Katze | G19: Gemüse, Obst und Faserstoffe | L19: Blüten, getrocknet | M19: =BF19 -> 0 | N19: =BG19 -> 0 | P19: =BI19 -> 0 | R19: =BK19 -> 0 | U19: =IF(S19="","",S19/T19) | BA19: 66 | BC19: Bio Blütenpollen | BD19: BARF Kultur | BE19: Einzelfuttermittel | BL19: 100% Bio Blütenpollen (Granulat) | BM19: https://www.barf-kultur.de/Bio-Bluetenpollen
D20: =E20&""&F20&""&G20&""&H20 -> EinzelfuttermittelKatzeGetreide, Samen, Leguminosen und Kartoffel-Produkte | E20: Einzelfuttermittel | F20: Katze | G20: Getreide, Samen, Leguminosen und Kartoffel-Produkte | L20: Buchweizenschälkleie | M20: =BF20 -> 1.6 | N20: =BG20 -> 14.5 | P20: =BI20 -> 3.3 | R20: =BK20 -> 1 | U20: =IF(S20="","",S20/T20) | AO20: 202 | AP20: 295 | AQ20: 190 | AR20: 463 | AS20: 11900 | AT20: 3600 | AU20: 1210 | AV20: 41561 | BA20: 263 | BB20: 0.25 | BC20: Buchweizenkeimpulver | BD20: BARF Kultur | BE20: Einzelfuttermittel | BF20: 1.6 | BG20: 14.5 | BI20: 3.3 | BK20: 1 | BL20: 100 % Buchweizenkeimpulver | BM20: https://www.barf-kultur.de/Buchweizenkeimpulver
D21: =E21&""&F21&""&G21&""&H21 -> EinzelfuttermittelKatzeFleisch-, Fisch- und Algenprodukte | E21: Einzelfuttermittel | F21: Katze | G21: Fleisch-, Fisch- und Algenprodukte | L21: Algen, getrocknet | M21: =BF21 -> 25 | N21: =BG21 -> 7.2 | P21: =BI21 -> 2.6 | R21: =BK21 -> 0 | U21: =IF(S21="","",S21/T21) | AD21: 80000 | AF21: =AG21*EFM!$BO$13 -> 0 | AL21: =AK21*EFM!$BO$14 -> 0 | BA21: 297.33 | BB21: 0.5 | BC21: DentaKomplex | BD21: VetConcept | BE21: Einzelfuttermittel | BF21: 25 | BG21: 7.2 | BI21: 2.6 | BL21: Naturreine Meeresalgen* , * getrocknet | BM21: https://www.vet-concept.at/p/fuer-die-katze-denta-komplex-60g-1
D22: =E22&""&F22&""&G22&""&H22 -> EinzelfuttermittelKatzeEi- und Milchprodukte | E22: Einzelfuttermittel | F22: Katze | G22: Ei- und Milchprodukte | L22: Eierschalen, getrocknet | M22: =BF22 -> 96 | N22: =BG22 -> 0 | P22: =BI22 -> 0 | R22: =BK22 -> 0 | S22: 37100 | T22: 1 | U22: =IF(S22="","",S22/T22) -> 37100 | AF22: =AG22*EFM!$BO$13 -> 0 | AL22: =AK22*EFM!$BO$14 -> 0 | BA22: 79.96 | BB22: 0.3 | BC22: Gemahlene Eierschalen | BD22: AniForte | BE22: Einzelfuttermittel | BF22: 96 | BL22: Eierschalen Pulver (37,1 % Calcium) | BM22: https://www.aniforte.de/products/eierschalen-pulver
D23: =E23&""&F23&""&G23&""&H23 -> EinzelfuttermittelKatzeGemüse, Obst und Faserstoffe | E23: Einzelfuttermittel | F23: Katze | G23: Gemüse, Obst und Faserstoffe | L23: Teufelskrallenwurzel, gemahlen | M23: =BF23 -> 5.5 | N23: =BG23 -> 3.67 | P23: =BI23 -> 0.5 | R23: =BK23 -> 5.1 | U23: =IF(S23="","",S23/T23) | BA23: 47.98 | BB23: 0.5 | BC23: Afrikanische Teufelskralle | BD23: AniForte | BE23: Einzelfuttermittel | BF23: 5.5 | BG23: 3.67 | BI23: 0.5 | BK23: 5.1 | BL23: Teufelskrallenwurzel gemahlen (1,3 % Harpagosid) | BM23: https://www.aniforte.de/products/afrikanische-teufelskralle
D24: =E24&""&F24&""&G24&""&H24 -> EinzelfuttermittelKatzeFleisch-, Fisch- und Algenprodukte | E24: Einzelfuttermittel | F24: Katze | G24: Fleisch-, Fisch- und Algenprodukte | L24: Weichtiermehl | M24: =BF24 -> 0 | N24: =BG24 -> 57.5 | P24: =BI24 -> 9.9 | R24: =BK24 -> 0 | U24: =IF(S24="","",S24/T24) | BA24: 133.27 | BB24: 1.5 | BC24: Canina Velox Gelenkenergie | BD24: Canina | BE24: Einzelfuttermittel | BG24: 57.5 | BI24: 9.9 | BL24: 100% Grünlipp-Muschelfleischmehl (Perna canaliculus) | BM24: https://www.fressnapf.at/p/canina-velox-gelenkenergie-150-g-1063316/
D25: =E25&""&F25&""&G25&""&H25 -> EinzelfuttermittelKatzeFleisch-, Fisch- und Algenprodukte | E25: Einzelfuttermittel | F25: Katze | G25: Fleisch-, Fisch- und Algenprodukte | L25: Seealgenmehl | M25: =BF25 -> 19.7 | N25: =BG25 -> 0 | P25: =BI25 -> 0 | R25: =BK25 -> 0 | U25: =IF(S25="","",S25/T25) | BA25: 20.65 | BB25: 3.5 | BC25: Canina Seealgenmehl | BD25: Canina | BE25: Einzelfuttermittel | BF25: 19.7 | BL25: Seealgen (Ascophyllum nodosum) | BM25: https://www.fressnapf.at/p/canina-seealgenmehl-750-g-1072170/?isSearchPage=canina
D26: =E26&""&F26&""&G26&""&H26 -> EinzelfuttermittelKatzeMineralstoffe | E26: Einzelfuttermittel | F26: Katze | G26: Mineralstoffe | L26: Torf | M26: =BF26 -> 0.4 | N26: =BG26 -> 0 | P26: =BI26 -> 0 | R26: =BK26 -> 2.4 | U26: =IF(S26="","",S26/T26) | BA26: 53.96 | BB26: 2.5 | BC26: Canina Moortränke | BD26: Canina | BE26: Einzelfuttermittel | BF26: 0.4 | BK26: 2.4 | BL26: naturbelassenes Moorwasser | BM26: https://www.fressnapf.at/p/canina-moortraenke-250ml-1264166/?isSearchPage=canina
D27: =E27&""&F27&""&G27&""&H27 -> EinzelfuttermittelKatzeEi- und Milchprodukte | E27: Einzelfuttermittel | F27: Katze | G27: Ei- und Milchprodukte | L27: Eierschalen, getrocknet | M27: =BF27 -> 96 | N27: =BG27 -> 0 | P27: =BI27 -> 0 | R27: =BK27 -> 0 | S27: 37000 | T27: 100 | U27: =IF(S27="","",S27/T27) -> 370 | BA27: 29.96 | BB27: 1.2 | BC27: Canina Eierschalenpulver | BD27: Canina | BE27: Einzelfuttermittel | BF27: 96 | BL27: 100 % Eierschale, gemahlen | BM27: https://canina.de/products/120208-eierschalenpulver?cat_id=27
D28: =E28&""&F28&""&G28&""&H28 -> EinzelfuttermittelKatzeGemüse, Obst und Faserstoffe | E28: Einzelfuttermittel | F28: Katze | G28: Gemüse, Obst und Faserstoffe | L28: Pulvercecllulose | M28: =BF28 -> 22 | N28: =BG28 -> 0 | P28: =BI28 -> 0 | R28: =BK28 -> 80 | U28: =IF(S28="","",S28/T28) | BA28: 34.98 | BB28: 4 | BC28: Canina Cellulosepulver | BD28: Canina | BE28: Einzelfuttermittel | BF28: 22 | BK28: 80 | BL28: Cellulose Pulver, 100% | BM28: https://canina.de/products/129003-cellulose-pulver?cat_id=21
D29: =E29&""&F29&""&G29&""&H29 -> EinzelfuttermittelKatzeInnereien, TNPs, Schlachtabfälle und Tiermehle | E29: Einzelfuttermittel | F29: Katze | G29: Innereien, TNPs, Schlachtabfälle und Tiermehle | L29: Blutmehl | M29: =BF29 -> 0 | N29: =BG29 -> 92 | P29: =BI29 -> 0 | R29: =BK29 -> 0 | U29: =IF(S29="","",S29/T29) | Z29: 250 | BA29: 31.96 | BB29: 1.2 | BC29: Canina Rinderblutpulver | BD29: Canina | BE29: Einzelfuttermittel | BG29: 92 | BL29: Bluterzeugnisse (getrocknetes Vollblut vom Rind) | BM29: https://canina.de/products/792016-rinderblutpulver?cat_id=27
D30: =E30&""&F30&""&G30&""&H30 -> EinzelfuttermittelKatzeFleisch-, Fisch- und Algenprodukte | E30: Einzelfuttermittel | F30: Katze | G30: Fleisch-, Fisch- und Algenprodukte | L30: Lithothamnium | M30: =BF30 -> 93.5 | N30: =BG30 -> 0.5 | P30: =BI30 -> 0.5 | R30: =BK30 -> 1 | S30: 3400 | T30: 40 | U30: =IF(S30="","",S30/T30) -> 85 | V30: 2340 | W30: 40 | X30: 730 | AD30: 2000 | BA30: 63.92 | BB30: 0.8 | BC30: Canina Algenkalk | BD30: Canina | BE30: Einzelfuttermittel | BF30: 93.5 | BG30: 0.5 | BI30: 0.5 | BK30: 1 | BL30: 100 % Kalkalge (Lithothamnium calcareum) | BM30: https://canina.de/products/100903-algenkalk?cat_id=23
D31: =E31&""&F31&""&G31&""&H31 -> EinzelfuttermittelKatzeGemüse, Obst und Faserstoffe | E31: Einzelfuttermittel | F31: Katze | G31: Gemüse, Obst und Faserstoffe | L31: Hefen, inaktiviert | M31: =BF31 -> 0 | N31: =BG31 -> 38.7 | P31: =BI31 -> 0 | R31: =BK31 -> 0 | U31: =IF(S31="","",S31/T31) | BA31: 112.6 | BC31: Bierhefe Tabs | BD31: Annimally | BE31: Einzelfuttermittel | BG31: 38.7 | BL31: 100 % Hefe (inaktivierte Saccharomyces cerevisiae) | BM31: https://www.annimally.at/products/bierhefe-hund-katze-kleintier?_gl=1*19rgle9*_up*MQ..&gclid=Cj0KCQjwo8S3BhDeARIsAFRmkOOkVlIfv6XQGMfHY9rb7s7ecTJjkN20Gmvh4Y3s66WGsIlr4ZT4mcsaAnwnEALw_wcB
D32: =E32&""&F32&""&G32&""&H32 -> EinzelfuttermittelKatzeFleisch-, Fisch- und Algenprodukte | E32: Einzelfuttermittel | F32: Katze | G32: Fleisch-, Fisch- und Algenprodukte | L32: Seealgenmehl | M32: =BF32 -> 17 | N32: =BG32 -> 6 | P32: =BI32 -> 0 | R32: =BK32 -> 6 | U32: =IF(S32="","",S32/T32) | BA32: 498.7 | BB32: 0.5 | BC32: PlaqueOff Pulver | BD32: ProDen | BE32: Einzelfuttermittel | BF32: 17 | BG32: 6 | BK32: 6 | BL32: 100% Seealgenmehl (Ascophyllum Nodosum) | BM32: https://www.drsam.de/produktseite/plaqueoff-pulver
D33: =E33&""&F33&""&G33&""&H33 -> EinzelfuttermittelKatzeFleisch-, Fisch- und Algenprodukte | E33: Einzelfuttermittel | F33: Katze | G33: Fleisch-, Fisch- und Algenprodukte | L33: Weichtiermehl | M33: =BF33 -> 0 | N33: =BG33 -> 61.1 | P33: =BI33 -> 11.5 | R33: =BK33 -> 0 | U33: =IF(S33="","",S33/T33) | BA33: 134.2 | BB33: 0.5 | BC33: Grünlippmuschelpulver | BD33: napfcheck | BE33: Einzelfuttermittel | BG33: 61.1 | BI33: 11.5 | BL33: 100% Muschelkonzentrat (neuseeländische Grünlippmuschel Perna canaliculus) | BM33: https://www.napfcheck-shop.at/produkt/napfcheck-gruenlippmuschel-fuer-hunde-und-katzen/
D34: =E34&""&F34&""&G34&""&H34 -> EinzelfuttermittelKatzeEi- und Milchprodukte | E34: Einzelfuttermittel | F34: Katze | G34: Ei- und Milchprodukte | L34: Eierschalen, getrocknet | M34: =BF34 -> 92.8 | N34: =BG34 -> 0 | P34: =BI34 -> 0 | R34: =BK34 -> 0 | S34: 35700 | T34: 100 | U34: =IF(S34="","",S34/T34) -> 357 | BA34: 27.8 | BB34: 0.5 | BC34: Eierschalenpulver - Hunde und Katzen | BD34: napfcheck | BE34: Einzelfuttermittel | BF34: 92.8 | BL34: 100 % Eierschale, gemahlen | BM34: https://www.napfcheck-shop.at/produkt/napfcheck-eierschalenpulver-fuer-hunde-und-katzen/
D35: =E35&""&F35&""&G35&""&H35 -> EinzelfuttermittelKatzeGemüse, Obst und Faserstoffe | E35: Einzelfuttermittel | F35: Katze | G35: Gemüse, Obst und Faserstoffe | L35: Cranberrypulver | M35: =BF35 -> 0 | N35: =BG35 -> 0 | P35: =BI35 -> 0 | R35: =BK35 -> 20.5 | U35: =IF(S35="","",S35/T35) | BA35: 59.5 | BB35: 1.5 | BC35: Cranberryfaser - Hunde und Katzen | BD35: napfcheck | BE35: Einzelfuttermittel | BK35: 20.5 | BL35: 100 % Cranberryfaser | BM35: https://www.napfcheck-shop.at/produkt/napfcheck-cranberryfaser-fuer-hunde-und-katzen/
D36: =E36&""&F36&""&G36&""&H36 -> EinzelfuttermittelKatzeFleisch-, Fisch- und Algenprodukte | E36: Einzelfuttermittel | F36: Katze | G36: Fleisch-, Fisch- und Algenprodukte | L36: Seealgenmehl | M36: =BF36 -> 11.2 | N36: =BG36 -> 0 | P36: =BI36 -> 0 | R36: =BK36 -> 0 | U36: =IF(S36="","",S36/T36) | AD36: 77000 | BA36: 44.5 | BB36: 0.15 | BC36: Seealgenmehl - Hunde und Katzen | BD36: napfcheck | BE36: Einzelfuttermittel | BF36: 11.2 | BL36: 100 % Bio Seealgenmehl (Ascophyllum nodosum) | BM36: https://www.napfcheck-shop.at/produkt/napfcheck-seealgenmehl-fuer-hunde-und-katzen/
D37: =E37&""&F37&""&G37&""&H37 -> EinzelfuttermittelKatzeFleisch-, Fisch- und Algenprodukte | E37: Einzelfuttermittel | F37: Katze | G37: Fleisch-, Fisch- und Algenprodukte | L37: Algen, getrocknet | M37: =BF37 -> 8.4 | N37: =BG37 -> 23.5 | P37: =BI37 -> 39.1 | R37: =BK37 -> 0 | U37: =IF(S37="","",S37/T37) | BA37: 127.6 | BB37: 0.08 | BC37: DHA Algenpulver - für Hunde und Katzen | BD37: napfcheck | BE37: Einzelfuttermittel | BF37: 8.4 | BG37: 23.5 | BI37: 39.1 | BK37: 0 | BL37: 100% Mikroalgenpulver (Schizochytrium sp.) | BM37: https://www.napfcheck-shop.at/produkt/napfcheck-dha-algenpulver-fuer-hunde-und-katzen/
D38: =E38&""&F38&""&G38&""&H38 -> EinzelfuttermittelKatzeGemüse, Obst und Faserstoffe | E38: Einzelfuttermittel | F38: Katze | G38: Gemüse, Obst und Faserstoffe | L38: Pulvercecllulose | M38: =BF38 -> 0 | N38: =BG38 -> 0 | P38: =BI38 -> 0 | R38: =BK38 -> 0 | U38: =IF(S38="","",S38/T38) | BA38: 19.45 | BB38: 3 | BC38: Futterzellulose - Hunde und Katzen | BD38: napfcheck | BE38: Einzelfuttermittel | BL38: 100% Pulverzellulose | BM38: https://www.napfcheck-shop.at/produkt/napfcheck-futterzellulose-fuer-hunde-katzen/
D39: =E39&""&F39&""&G39&""&H39 -> EinzelfuttermittelKatzeGetreide, Samen, Leguminosen und Kartoffel-Produkte | E39: Einzelfuttermittel | F39: Katze | G39: Getreide, Samen, Leguminosen und Kartoffel-Produkte | L39: Spitzwegerich-Saat | M39: =BF39 -> 0 | N39: =BG39 -> 0 | P39: =BI39 -> 0 | R39: =BK39 -> 90 | U39: =IF(S39="","",S39/T39) | BA39: 43 | BB39: 3 | BC39: Flohsamenschalen gemahlen | BD39: napfcheck | BE39: Einzelfuttermittel | BK39: 90 | BL39: 100% Flohsamenschalen, gemahlen | BM39: https://www.napfcheck-shop.at/produkt/napfcheck-flohsamenschalen-gemahlen-fuer-hunde-und-katzen/
A40: Fische und Algen | D40: =E40&""&F40&""&G40&""&H40 -> EinzelfuttermittelKatzeFleisch-, Fisch- und Algenprodukte | E40: Einzelfuttermittel | F40: Katze | G40: Fleisch-, Fisch- und Algenprodukte | L40: Weichtiermehl | M40: =BF40 -> 14.1 | N40: =BG40 -> 52 | P40: =BI40 -> 2.3 | R40: =BK40 -> 0 | U40: =IF(S40="","",S40/T40) | BA40: 102.4 | BB40: 2 | BC40: Grünlippmuschelpulver | BD40: Grau | BE40: Einzelfuttermittel | BF40: 14.1 | BG40: 52 | BI40: 2.3 | BL40: Muschelpulver (100 %, Perna canaliculus) | BM40: https://www.grau-generationpet.de/00001184/gruenlippmuschel-pulver
...
